2020-12-24 01:46:29,497 - root - INFO - main.py:58 - START SERVER
2020-12-24 01:46:29,704 - root - INFO - gateway_server.py:257 - 服务端(('192.168.0.102', 8000))已成功连接。。online
2020-12-24 01:46:29,803 - root - INFO - base_adapter.py:58 - 调用的库：/home/alex/PycharmProjects/ToolManageSys/util/hkws/../libs/hkvision_lib/libhcnetsdk.so
2020-12-24 01:46:29,803 - root - INFO - base_adapter.py:59 - 执行成功,返回值：1
2020-12-24 01:46:29,803 - root - INFO - base_adapter.py:74 - SDK初始化成功
2020-12-24 01:46:29,804 - root - INFO - base_adapter.py:58 - 调用的库：/home/alex/PycharmProjects/ToolManageSys/util/hkws/../libs/hkvision_lib/libhcnetsdk.so
2020-12-24 01:46:29,805 - root - INFO - base_adapter.py:59 - 执行成功,返回值：1
2020-12-24 01:46:29,806 - root - INFO - base_adapter.py:58 - 调用的库：/home/alex/PycharmProjects/ToolManageSys/util/hkws/../libs/hkvision_lib/libhcnetsdk.so
2020-12-24 01:46:29,806 - root - INFO - base_adapter.py:59 - 执行成功,返回值：1
2020-12-24 01:46:32,720 - root - INFO - base_adapter.py:58 - 调用的库：/home/alex/PycharmProjects/ToolManageSys/util/hkws/../libs/hkvision_lib/libhcnetsdk.so
2020-12-24 01:46:32,720 - root - INFO - base_adapter.py:59 - 执行成功,返回值：-1
2020-12-24 01:46:32,721 - root - INFO - base_adapter.py:58 - 调用的库：/home/alex/PycharmProjects/ToolManageSys/util/hkws/../libs/hkvision_lib/libhcnetsdk.so
2020-12-24 01:46:32,721 - root - INFO - base_adapter.py:59 - 执行成功,返回值：7
2020-12-24 01:46:32,721 - root - ERROR - base_adapter.py:219 - NET_DVR_Login_V40 用户登录失败: the error code is 7
2020-12-24 01:46:32,724 - root - INFO - gateway_server.py:257 - 服务端(('192.168.0.201', 4370))已成功连接。。online
2020-12-24 01:46:32,735 - root - INFO - base_adapter.py:58 - 调用的库：/home/alex/PycharmProjects/ToolManageSys/util/hkws/../libs/hkvision_lib/libhcnetsdk.so
2020-12-24 01:46:32,740 - root - ERROR - Object2.py:890 - (192.168.0.201, 4370)--GetDeviceDataCount() get error code -6
2020-12-24 01:46:32,746 - root - INFO - base_adapter.py:59 - 执行成功,返回值：7
2020-12-24 01:46:32,746 - root - ERROR - base_adapter.py:219 - common_start 失败: the error code is7
2020-12-24 01:46:32,747 - root - WARNING - Object2.py:832 - Entrance_zk (192.168.0.201, 4370) try to offline
2020-12-24 01:46:32,806 - root - INFO - base_adapter.py:58 - 调用的库：/home/alex/PycharmProjects/ToolManageSys/util/hkws/../libs/hkvision_lib/libhcnetsdk.so
2020-12-24 01:46:32,806 - root - INFO - base_adapter.py:59 - 执行成功,返回值：1
2020-12-24 01:46:32,806 - root - INFO - base_adapter.py:98 - 释放资源, result=1
2020-12-24 01:46:32,881 - root - WARNING - gateway_server.py:265 - fail to connect to server ('192.168.0.118', 23)
2020-12-24 01:46:32,983 - root - WARNING - gateway_server.py:265 - fail to connect to server ('192.168.0.117', 26)
2020-12-24 01:46:33,084 - root - WARNING - gateway_server.py:265 - fail to connect to server ('192.168.0.117', 23)
2020-12-24 01:46:33,187 - root - WARNING - gateway_server.py:265 - fail to connect to server ('192.168.0.117', 23)
2020-12-24 01:46:33,290 - root - WARNING - gateway_server.py:265 - fail to connect to server ('192.168.0.118', 23)
2020-12-24 01:46:33,396 - root - WARNING - gateway_server.py:265 - fail to connect to server ('192.168.0.117', 26)
2020-12-24 01:46:34,088 - root - WARNING - gateway_server.py:106 - equipment (192.168.0.102, 8000) is offline
2020-12-24 01:46:34,089 - root - WARNING - gateway_server.py:106 - equipment (192.168.0.201, 4370) is offline
2020-12-24 01:51:16,006 - root - INFO - main.py:53 - START SERVER
2020-12-24 01:51:16,115 - root - INFO - gateway_server.py:187 - 服务端(('192.168.0.102', 8000))已成功连接。。online
2020-12-24 01:51:16,187 - root - INFO - base_adapter.py:58 - 调用的库：/home/alex/PycharmProjects/ToolManageSys/util/hkws/../libs/hkvision_lib/libhcnetsdk.so
2020-12-24 01:51:16,187 - root - INFO - base_adapter.py:59 - 执行成功,返回值：1
2020-12-24 01:51:16,188 - root - INFO - base_adapter.py:74 - SDK初始化成功
2020-12-24 01:51:16,192 - root - INFO - base_adapter.py:58 - 调用的库：/home/alex/PycharmProjects/ToolManageSys/util/hkws/../libs/hkvision_lib/libhcnetsdk.so
2020-12-24 01:51:16,192 - root - INFO - base_adapter.py:59 - 执行成功,返回值：1
2020-12-24 01:51:16,196 - root - INFO - base_adapter.py:58 - 调用的库：/home/alex/PycharmProjects/ToolManageSys/util/hkws/../libs/hkvision_lib/libhcnetsdk.so
2020-12-24 01:51:16,196 - root - INFO - base_adapter.py:59 - 执行成功,返回值：1
2020-12-24 01:51:19,123 - root - INFO - base_adapter.py:58 - 调用的库：/home/alex/PycharmProjects/ToolManageSys/util/hkws/../libs/hkvision_lib/libhcnetsdk.so
2020-12-24 01:51:19,124 - root - INFO - base_adapter.py:59 - 执行成功,返回值：-1
2020-12-24 01:51:19,125 - root - INFO - base_adapter.py:58 - 调用的库：/home/alex/PycharmProjects/ToolManageSys/util/hkws/../libs/hkvision_lib/libhcnetsdk.so
2020-12-24 01:51:19,125 - root - INFO - base_adapter.py:59 - 执行成功,返回值：7
2020-12-24 01:51:19,125 - root - ERROR - base_adapter.py:219 - NET_DVR_Login_V40 用户登录失败: the error code is 7
2020-12-24 01:51:19,127 - root - INFO - base_adapter.py:58 - 调用的库：/home/alex/PycharmProjects/ToolManageSys/util/hkws/../libs/hkvision_lib/libhcnetsdk.so
2020-12-24 01:51:19,127 - root - INFO - base_adapter.py:59 - 执行成功,返回值：7
2020-12-24 01:51:19,127 - root - ERROR - base_adapter.py:219 - common_start 失败: the error code is7
2020-12-24 01:51:19,131 - root - INFO - gateway_server.py:187 - 服务端(('192.168.0.201', 4370))已成功连接。。online
2020-12-24 01:51:19,137 - root - ERROR - Object2.py:890 - (192.168.0.201, 4370)--GetDeviceDataCount() get error code -6
2020-12-24 01:51:19,149 - root - WARNING - Object2.py:832 - Entrance_zk (192.168.0.201, 4370) try to offline
2020-12-24 01:51:19,190 - root - INFO - base_adapter.py:58 - 调用的库：/home/alex/PycharmProjects/ToolManageSys/util/hkws/../libs/hkvision_lib/libhcnetsdk.so
2020-12-24 01:51:19,190 - root - INFO - base_adapter.py:59 - 执行成功,返回值：1
2020-12-24 01:51:19,190 - root - INFO - base_adapter.py:98 - 释放资源, result=1
2020-12-24 01:51:19,267 - root - WARNING - gateway_server.py:195 - fail to connect to server ('192.168.0.118', 23)
2020-12-24 01:51:19,368 - root - WARNING - gateway_server.py:195 - fail to connect to server ('192.168.0.117', 26)
2020-12-24 01:51:19,470 - root - WARNING - gateway_server.py:195 - fail to connect to server ('192.168.0.117', 23)
2020-12-24 01:51:19,572 - root - WARNING - gateway_server.py:195 - fail to connect to server ('192.168.0.117', 26)
2020-12-24 01:51:19,677 - root - WARNING - gateway_server.py:195 - fail to connect to server ('192.168.0.117', 23)
2020-12-24 01:51:19,781 - root - WARNING - gateway_server.py:195 - fail to connect to server ('192.168.0.118', 23)
2020-12-24 01:51:20,473 - root - WARNING - gateway_server.py:106 - equipment (192.168.0.102, 8000) is offline
2020-12-24 01:51:20,474 - root - WARNING - gateway_server.py:106 - equipment (192.168.0.201, 4370) is offline
