2020-12-07 13:44:03,565 - root - INFO - main.py:60 - START SERVER
2020-12-07 13:44:04,210 - root - INFO - gateway_server.py:239 - 服务端(('192.168.0.201', 4370))已成功连接。。online
2020-12-07 13:44:04,258 - root - INFO - gateway_server.py:239 - 服务端(('192.168.0.117', 26))已成功连接。。online
2020-12-07 13:44:04,274 - root - INFO - gateway_server.py:239 - 服务端(('192.168.0.117', 23))已成功连接。。online
2020-12-07 13:44:04,277 - root - WARNING - gateway_server.py:412 - Not found object(192.168.0.117,23) from DB-collector while updating
2020-12-07 13:44:05,000 - root - INFO - gateway_server.py:291 - 客户端(('192.168.0.97', 23))连接创建线程失败。。
2020-12-07 13:44:05,009 - root - INFO - gateway_server.py:287 - 客户端(('192.168.0.97', 26))已成功连接。。online
2020-12-07 13:44:06,010 - root - INFO - gateway_server.py:291 - 客户端(('192.168.0.97', 23))连接创建线程失败。。
2020-12-07 13:51:02,094 - root - INFO - main.py:60 - START SERVER
2020-12-07 13:51:02,696 - root - INFO - gateway_server.py:239 - 服务端(('192.168.0.201', 4370))已成功连接。。online
2020-12-07 13:51:02,715 - root - INFO - gateway_server.py:239 - 服务端(('192.168.0.117', 26))已成功连接。。online
2020-12-07 13:51:02,721 - root - INFO - gateway_server.py:239 - 服务端(('192.168.0.117', 23))已成功连接。。online
2020-12-07 13:51:02,724 - root - WARNING - gateway_server.py:412 - Not found object(192.168.0.117,23) from DB-collector while updating
2020-12-07 13:51:02,731 - root - INFO - gateway_server.py:239 - 服务端(('192.168.0.117', 26))已成功连接。。online
2020-12-07 13:51:03,238 - root - INFO - gateway_server.py:291 - 客户端(('192.168.0.97', 23))连接创建线程失败。。
2020-12-07 13:51:03,272 - root - INFO - gateway_server.py:287 - 客户端(('192.168.0.97', 26))已成功连接。。online
2020-12-07 13:51:04,324 - root - INFO - gateway_server.py:291 - 客户端(('192.168.0.97', 23))连接创建线程失败。。
2020-12-07 13:53:52,388 - root - INFO - main.py:60 - START SERVER
2020-12-07 13:53:52,986 - root - INFO - gateway_server.py:239 - 服务端(('192.168.0.201', 4370))已成功连接。。online
2020-12-07 13:53:53,000 - root - INFO - gateway_server.py:239 - 服务端(('192.168.0.117', 26))已成功连接。。online
2020-12-07 13:53:53,007 - root - INFO - gateway_server.py:239 - 服务端(('192.168.0.117', 23))已成功连接。。online
2020-12-07 13:53:53,011 - root - WARNING - gateway_server.py:412 - Not found object(192.168.0.117,23) from DB-collector while updating
2020-12-07 13:53:53,978 - root - INFO - gateway_server.py:291 - 客户端(('192.168.0.97', 23))连接创建线程失败。。
2020-12-07 13:53:54,009 - root - INFO - gateway_server.py:287 - 客户端(('192.168.0.97', 26))已成功连接。。online
2020-12-07 13:53:55,005 - root - INFO - gateway_server.py:291 - 客户端(('192.168.0.97', 23))连接创建线程失败。。
2020-12-07 13:56:38,999 - root - INFO - main.py:60 - START SERVER
2020-12-07 13:56:39,600 - root - INFO - gateway_server.py:239 - 服务端(('192.168.0.201', 4370))已成功连接。。online
2020-12-07 13:56:39,613 - root - INFO - gateway_server.py:239 - 服务端(('192.168.0.117', 26))已成功连接。。online
2020-12-07 13:56:39,623 - root - INFO - gateway_server.py:239 - 服务端(('192.168.0.117', 23))已成功连接。。online
2020-12-07 13:56:39,628 - root - WARNING - gateway_server.py:412 - Not found object(192.168.0.117,23) from DB-collector while updating
2020-12-07 13:56:40,225 - root - INFO - gateway_server.py:291 - 客户端(('192.168.0.97', 23))连接创建线程失败。。
2020-12-07 13:56:40,262 - root - INFO - gateway_server.py:287 - 客户端(('192.168.0.97', 26))已成功连接。。online
2020-12-07 13:56:41,229 - root - INFO - gateway_server.py:291 - 客户端(('192.168.0.97', 23))连接创建线程失败。。
2020-12-07 14:02:53,107 - root - INFO - main.py:60 - START SERVER
2020-12-07 14:02:53,714 - root - INFO - gateway_server.py:239 - 服务端(('192.168.0.201', 4370))已成功连接。。online
2020-12-07 14:02:53,726 - root - INFO - gateway_server.py:239 - 服务端(('192.168.0.117', 26))已成功连接。。online
2020-12-07 14:02:53,732 - root - INFO - gateway_server.py:239 - 服务端(('192.168.0.117', 23))已成功连接。。online
2020-12-07 14:02:53,734 - root - WARNING - gateway_server.py:412 - Not found object(192.168.0.117,23) from DB-collector while updating
2020-12-07 14:02:53,753 - root - INFO - gateway_server.py:239 - 服务端(('192.168.0.117', 23))已成功连接。。online
2020-12-07 14:02:53,756 - root - WARNING - gateway_server.py:412 - Not found object(192.168.0.117,23) from DB-collector while updating
2020-12-07 14:02:54,127 - root - INFO - gateway_server.py:291 - 客户端(('192.168.0.97', 23))连接创建线程失败。。
2020-12-07 14:02:54,139 - root - INFO - gateway_server.py:287 - 客户端(('192.168.0.97', 26))已成功连接。。online
2020-12-07 14:02:55,136 - root - INFO - gateway_server.py:291 - 客户端(('192.168.0.97', 23))连接创建线程失败。。
2020-12-07 14:04:22,337 - root - INFO - main.py:60 - START SERVER
2020-12-07 14:04:22,962 - root - INFO - gateway_server.py:239 - 服务端(('192.168.0.201', 4370))已成功连接。。online
2020-12-07 14:04:22,975 - root - INFO - gateway_server.py:239 - 服务端(('192.168.0.117', 26))已成功连接。。online
2020-12-07 14:04:22,980 - root - INFO - gateway_server.py:239 - 服务端(('192.168.0.117', 23))已成功连接。。online
2020-12-07 14:04:22,983 - root - WARNING - gateway_server.py:412 - Not found object(192.168.0.117,23) from DB-collector while updating
2020-12-07 14:04:23,058 - root - INFO - gateway_server.py:291 - 客户端(('192.168.0.97', 23))连接创建线程失败。。
2020-12-07 14:04:23,061 - root - INFO - gateway_server.py:287 - 客户端(('192.168.0.97', 26))已成功连接。。online
2020-12-07 14:04:24,067 - root - INFO - gateway_server.py:291 - 客户端(('192.168.0.97', 23))连接创建线程失败。。
2020-12-07 14:05:40,290 - root - ERROR - task_controler.py:163 - 'queue'
2020-12-07 14:06:42,589 - root - INFO - main.py:60 - START SERVER
2020-12-07 14:06:43,247 - root - INFO - gateway_server.py:239 - 服务端(('192.168.0.201', 4370))已成功连接。。online
2020-12-07 14:06:43,265 - root - INFO - gateway_server.py:239 - 服务端(('192.168.0.117', 26))已成功连接。。online
2020-12-07 14:06:43,272 - root - INFO - gateway_server.py:239 - 服务端(('192.168.0.117', 23))已成功连接。。online
2020-12-07 14:06:43,275 - root - WARNING - gateway_server.py:412 - Not found object(192.168.0.117,23) from DB-collector while updating
2020-12-07 14:06:43,289 - root - INFO - gateway_server.py:239 - 服务端(('192.168.0.117', 26))已成功连接。。online
2020-12-07 14:06:44,020 - root - INFO - gateway_server.py:291 - 客户端(('192.168.0.97', 23))连接创建线程失败。。
2020-12-07 14:06:44,024 - root - INFO - gateway_server.py:287 - 客户端(('192.168.0.97', 26))已成功连接。。online
2020-12-07 14:06:45,033 - root - INFO - gateway_server.py:291 - 客户端(('192.168.0.97', 23))连接创建线程失败。。
2020-12-07 14:07:50,215 - root - ERROR - task_controler.py:163 - 'queue'
2020-12-07 14:09:29,284 - root - WARNING - gateway_server.py:105 - equipment (192.168.0.201, 4370) is offline
2020-12-07 14:09:31,179 - root - ERROR - Object2.py:60 - 'int' object is not iterable
2020-12-07 14:09:31,523 - root - INFO - gateway_server.py:239 - 服务端(('192.168.0.201', 4370))已成功连接。。online
2020-12-07 14:09:31,656 - root - WARNING - gateway_server.py:247 - fail to connect to server ('192.168.0.117', 23)
2020-12-07 14:09:32,454 - root - WARNING - gateway_server.py:105 - equipment (192.168.0.201, 4370) is offline
2020-12-07 14:09:41,169 - root - ERROR - Object2.py:60 - 'int' object is not iterable
2020-12-07 14:09:50,371 - root - INFO - main.py:60 - START SERVER
2020-12-07 14:09:50,970 - root - INFO - gateway_server.py:239 - 服务端(('192.168.0.201', 4370))已成功连接。。online
2020-12-07 14:09:50,982 - root - INFO - gateway_server.py:239 - 服务端(('192.168.0.117', 26))已成功连接。。online
2020-12-07 14:09:50,988 - root - INFO - gateway_server.py:239 - 服务端(('192.168.0.117', 23))已成功连接。。online
2020-12-07 14:09:50,990 - root - WARNING - gateway_server.py:412 - Not found object(192.168.0.117,23) from DB-collector while updating
2020-12-07 14:09:50,995 - root - INFO - gateway_server.py:239 - 服务端(('192.168.0.117', 26))已成功连接。。online
2020-12-07 14:09:51,767 - root - INFO - gateway_server.py:291 - 客户端(('192.168.0.97', 23))连接创建线程失败。。
2020-12-07 14:09:51,793 - root - INFO - gateway_server.py:287 - 客户端(('192.168.0.97', 26))已成功连接。。online
2020-12-07 14:09:52,792 - root - INFO - gateway_server.py:291 - 客户端(('192.168.0.97', 23))连接创建线程失败。。
2020-12-07 14:10:24,382 - root - ERROR - task_controler.py:163 - 'queue'
2020-12-07 14:15:40,486 - root - INFO - main.py:60 - START SERVER
2020-12-07 14:15:41,085 - root - INFO - gateway_server.py:239 - 服务端(('192.168.0.201', 4370))已成功连接。。online
2020-12-07 14:15:41,098 - root - INFO - gateway_server.py:239 - 服务端(('192.168.0.117', 26))已成功连接。。online
2020-12-07 14:15:41,105 - root - INFO - gateway_server.py:239 - 服务端(('192.168.0.117', 23))已成功连接。。online
2020-12-07 14:15:41,108 - root - WARNING - gateway_server.py:412 - Not found object(192.168.0.117,23) from DB-collector while updating
2020-12-07 14:15:41,114 - root - INFO - gateway_server.py:239 - 服务端(('192.168.0.117', 23))已成功连接。。online
2020-12-07 14:15:41,119 - root - WARNING - gateway_server.py:412 - Not found object(192.168.0.117,23) from DB-collector while updating
2020-12-07 14:15:41,606 - root - INFO - gateway_server.py:291 - 客户端(('192.168.0.97', 23))连接创建线程失败。。
2020-12-07 14:15:41,622 - root - INFO - gateway_server.py:287 - 客户端(('192.168.0.97', 26))已成功连接。。online
2020-12-07 14:15:42,629 - root - INFO - gateway_server.py:291 - 客户端(('192.168.0.97', 23))连接创建线程失败。。
2020-12-07 14:16:07,034 - root - ERROR - task_controler.py:167 - 'queue'
2020-12-07 14:18:45,245 - root - INFO - main.py:60 - START SERVER
2020-12-07 14:18:45,845 - root - INFO - gateway_server.py:239 - 服务端(('192.168.0.201', 4370))已成功连接。。online
2020-12-07 14:18:45,858 - root - INFO - gateway_server.py:239 - 服务端(('192.168.0.117', 26))已成功连接。。online
2020-12-07 14:18:45,864 - root - INFO - gateway_server.py:239 - 服务端(('192.168.0.117', 23))已成功连接。。online
2020-12-07 14:18:45,867 - root - WARNING - gateway_server.py:412 - Not found object(192.168.0.117,23) from DB-collector while updating
2020-12-07 14:18:46,567 - root - INFO - gateway_server.py:291 - 客户端(('192.168.0.97', 23))连接创建线程失败。。
2020-12-07 14:18:46,601 - root - INFO - gateway_server.py:287 - 客户端(('192.168.0.97', 26))已成功连接。。online
2020-12-07 14:18:47,585 - root - INFO - gateway_server.py:291 - 客户端(('192.168.0.97', 23))连接创建线程失败。。
2020-12-07 14:25:48,240 - root - INFO - main.py:60 - START SERVER
2020-12-07 14:25:48,997 - root - INFO - gateway_server.py:239 - 服务端(('192.168.0.201', 4370))已成功连接。。online
2020-12-07 14:25:49,030 - root - INFO - gateway_server.py:239 - 服务端(('192.168.0.117', 26))已成功连接。。online
2020-12-07 14:25:49,038 - root - INFO - gateway_server.py:239 - 服务端(('192.168.0.117', 23))已成功连接。。online
2020-12-07 14:25:49,042 - root - WARNING - gateway_server.py:412 - Not found object(192.168.0.117,23) from DB-collector while updating
2020-12-07 14:25:49,052 - root - INFO - gateway_server.py:239 - 服务端(('192.168.0.117', 23))已成功连接。。online
2020-12-07 14:25:49,059 - root - WARNING - gateway_server.py:412 - Not found object(192.168.0.117,23) from DB-collector while updating
2020-12-07 14:25:49,705 - root - INFO - gateway_server.py:291 - 客户端(('192.168.0.97', 23))连接创建线程失败。。
2020-12-07 14:25:49,744 - root - INFO - gateway_server.py:287 - 客户端(('192.168.0.97', 26))已成功连接。。online
2020-12-07 14:25:50,729 - root - INFO - gateway_server.py:291 - 客户端(('192.168.0.97', 23))连接创建线程失败。。
2020-12-07 14:26:05,822 - root - ERROR - task_controler.py:324 - get no user by code 222222222
2020-12-07 14:26:53,612 - root - INFO - main.py:60 - START SERVER
2020-12-07 14:26:54,276 - root - INFO - gateway_server.py:239 - 服务端(('192.168.0.201', 4370))已成功连接。。online
2020-12-07 14:26:54,318 - root - INFO - gateway_server.py:239 - 服务端(('192.168.0.117', 26))已成功连接。。online
2020-12-07 14:26:54,347 - root - INFO - gateway_server.py:239 - 服务端(('192.168.0.117', 23))已成功连接。。online
2020-12-07 14:26:54,351 - root - WARNING - gateway_server.py:412 - Not found object(192.168.0.117,23) from DB-collector while updating
2020-12-07 14:26:54,456 - root - INFO - gateway_server.py:291 - 客户端(('192.168.0.97', 23))连接创建线程失败。。
2020-12-07 14:26:54,467 - root - INFO - gateway_server.py:287 - 客户端(('192.168.0.97', 26))已成功连接。。online
2020-12-07 14:26:55,466 - root - INFO - gateway_server.py:291 - 客户端(('192.168.0.97', 23))连接创建线程失败。。
2020-12-07 14:27:08,067 - root - ERROR - task_controler.py:325 - get no user by code 222222222
2020-12-07 14:27:20,456 - root - ERROR - task_controler.py:325 - get no user by code 222222222
2020-12-07 14:27:26,654 - root - ERROR - task_controler.py:325 - get no user by code 222222222
2020-12-07 14:27:32,850 - root - ERROR - task_controler.py:325 - get no user by code 222222222
2020-12-07 14:33:21,500 - root - ERROR - Object2.py:60 - 'int' object has no attribute 'hex'
2020-12-07 14:40:51,842 - root - ERROR - Object2.py:60 - 'int' object has no attribute 'hex'
2020-12-07 14:41:21,231 - root - ERROR - Object2.py:60 - 'int' object has no attribute 'hex'
